<?xml version="1.0"?>
<robot name="swiftpro" xmlns:xacro="http://ros.org/wiki/xacro">
  <xacro:include filename="$(find oryxbot_description)/xacro/swiftpro_gazebo_plugin.xacro" />
  <xacro:macro name="uarm_swiftpro" params="prefix parent xyz rpy sim">
    <joint name="${prefix}/arm_joint" type="fixed">
      <parent link="${parent}" />
      <child link="${prefix}/base_link" />
      <origin xyz="${xyz}" rpy="${rpy}" />
      <axis xyz="0 0 0" />
    </joint>

    <link name="${prefix}/base_link">
      <inertial>
        <origin xyz="0.010476 0.000747 0.035226" rpy="0 0 0" />
        <mass value="0.1" />
        <inertia ixx="0.001196219" ixy="-0.000029358" ixz="0.000014859"
          iyy="0.001147997" iyz="0.000016274" izz="0.001425617" />
      </inertial>
      <visual>
        <geometry>
          <mesh filename="package://oryxbot_description/meshes/swiftpro/Base.STL" />
        </geometry>
        <origin xyz="0 0 0 " rpy="0 0 0" />
        <material name="">
          <color rgba="0.3 0.3 0.3 1" />
        </material>
      </visual>
      <collision>
        <geometry>
          <mesh filename="package://oryxbot_description/meshes/swiftpro/Base.STL" />
        </geometry>
        <origin xyz="0 0 0 " rpy="0 0 0" />
        <material name="">
          <color rgba="0.3 0.3 0.3 1" />
        </material>
      </collision>
    </link>
    <joint name="${prefix}/arm_joint1" type="revolute">
      <axis xyz="0 0 1" />
      <limit effort="150" lower="-3" upper="3" velocity="0.0" />
      <parent link="${prefix}/base_link" />
      <child link="${prefix}/arm_link1" />
      <origin xyz="0 0 0.0723" rpy=" 0 0 0" />
    </joint>

    <link name="${prefix}/arm_link1">
      <inertial>
        <origin rpy="0 0 0" xyz="-0.002175 0 0.029097" />
        <mass value="0.001" />
        <inertia ixx="0.000496945" ixy="-0.000000082" ixz="-0.000002744" iyy="0.000150389" iyz="-0.000000002" izz="0.000522487" />
    </inertial>
      <visual>
        <geometry>
          <mesh filename="package://oryxbot_description/meshes/swiftpro/Link1.STL" />
        </geometry>
        <origin xyz="0 0 -0.0723" rpy="0 0 0" />
        <material name="">
          <color rgba="0.3 0.3 0.3 1" />
        </material>
      </visual>
      <collision>
        <geometry>
          <mesh filename="package://oryxbot_description/meshes/swiftpro/Link1.STL" />
        </geometry>
        <origin xyz="0 0 -0.0723" rpy="0 0 0" />
        <material name="">
          <color rgba="0.3 0.3 0.3 1" />
        </material>
      </collision>
    </link>
    <joint name="${prefix}/arm_joint2" type="revolute">
      <axis xyz="0 1 0" />
      <limit effort="150" lower="-3" upper="3" velocity="0.0" />
      <parent link="${prefix}/arm_link1" />
      <child link="${prefix}/arm_link2" />
      <origin xyz="0.0132 0 0.0333" rpy=" 0 0 0" />
    </joint>

    <link name="${prefix}/arm_link2">
      <inertial>
        <origin xyz="-0.001071 0.001101 0.053193" rpy="0 0 0" />
        <mass value="0.001" />
        <inertia ixx="0.000061744" ixy="-0.000000025" ixz="-0.000000763"
          iyy="0.000062096" iyz="-0.000001053" izz="0.000002942" />
      </inertial>
      <visual>
        <geometry>
          <mesh filename="package://oryxbot_description/meshes/swiftpro/Link2.STL" />
        </geometry>
        <origin xyz="-0.0132 0 -0.1056" rpy="0 0 0" />
        <material name="">
          <color rgba="0.3 0.3 0.3 1" />
        </material>
      </visual>
      <collision>
        <geometry>
          <mesh filename="package://oryxbot_description/meshes/swiftpro/Link2.STL" />
        </geometry>
        <origin xyz="-0.0132 0 -0.1056" rpy="0 0 0" />
        <material name="">
          <color rgba="0.3 0.3 0.3 1" />
        </material>
      </collision>
    </link>
    <joint name="${prefix}/arm_joint3" type="revolute">
      <axis xyz="0 1 0" />
      <parent link="${prefix}/arm_link2" />
      <child link="${prefix}/arm_link3" />
      <limit effort="150" lower="-1.45" upper="1.45" velocity="0.0" />
      <origin xyz="0 0 0.14207 " rpy="0 0 0" />
    </joint>

    <link name="${prefix}/arm_link3">
      <inertial>
        <origin xyz="0.101948 -0.00022 0.011917" rpy="0 0 0" />
        <mass value="0.001" />
        <inertia ixx="0.000001982" ixy="0.000000483" ixz="-0.000005373"
          iyy="0.000081264" iyz="0.000000008" izz="0.000080538" />
      </inertial>
      <visual>
        <geometry>
          <mesh filename="package://oryxbot_description/meshes/swiftpro/Link3.STL" />
        </geometry>
        <origin xyz="-0.0132 0 -0.24767"
          rpy="0 0 0" />
        <material name="">
          <color rgba="0.3 0.3 0.3 1" />
        </material>
      </visual>
      <collision>
        <geometry>
          <mesh filename="package://oryxbot_description/meshes/swiftpro/Link3.STL" />
        </geometry>
        <origin xyz="-0.0132 0 -0.24767" />
        <material name="">
          <color rgba="0.3 0.3 0.3 1" />
        </material>
      </collision>
    </link>
    <joint name="${prefix}/arm_joint4" type="revolute">
      <axis xyz="0 1 0" />
      <limit effort="150" lower="-3" upper="3" velocity="0.0" />
      <parent link="${prefix}/arm_link2" />
      <child link="${prefix}/arm_link4" />
      <origin xyz="0 0 0.14207" rpy=" 0 0 0" />
    </joint>

    <link name="${prefix}/arm_link4">
      <inertial>
        <origin xyz="-0.00235 0.013618 0.015458" rpy="0 0 0" />
        <mass value="0.001" />
        <inertia ixx="0.000000316" ixy="0.000000001" ixz="0.000000177"
          iyy="0.000001679" iyz="-0.000000007" izz="0.000001378" />
      </inertial>
      <visual>
        <geometry>
          <mesh filename="package://oryxbot_description/meshes/swiftpro/Link4.STL" />
        </geometry>
        <origin xyz="-0.0132 0 -0.24767" rpy="0 0 0" />
        <material name="">
          <color rgba="0.3 0.3 0.3 1" />
        </material>
      </visual>
      <collision>
        <geometry>
          <mesh filename="package://oryxbot_description/meshes/swiftpro/Link4.STL" />
        </geometry>
        <origin xyz="-0.0132 0 -0.24767" rpy="0 0 0" />
        <material name="">
          <color rgba="0.3 0.3 0.3 1" />
        </material>
      </collision>
    </link>
    <joint name="${prefix}/arm_joint5" type="revolute">
      <axis xyz="0 1 0" />
      <limit effort="150" lower="-3" upper="3" velocity="0.0" />
      <parent link="${prefix}/arm_link1" />
      <child link="${prefix}/arm_link5" />
      <origin xyz="-0.0215 0 0.05001" rpy=" 0 0 0" />
    </joint>
    
    <link name="${prefix}/arm_link5">
      <inertial>
        <origin xyz="0.000287 0.0157 0.072444" rpy="0 0 0" />
        <mass value="0.001" />
        <inertia ixx="0.000004841" ixy="0.000000000" ixz="0.000000023"
          iyy="0.000004863" iyz="0.000000000" izz="0.000000023" />
      </inertial>
      <visual>
        <geometry>
          <mesh filename="package://oryxbot_description/meshes/swiftpro/Link5.STL" />
        </geometry>
        <origin xyz="0.0215 0 -0.1223" rpy="0 0 0" />
        <material name="">
          <color rgba="0.3 0.3 0.3 1" />
        </material>
      </visual>
      <collision>
        <geometry>
          <mesh filename="package://oryxbot_description/meshes/swiftpro/Link5.STL" />
        </geometry>
        <origin xyz="0.0215 0 -0.1223" rpy="0 0 0" />
        <material name="">
          <color rgba="0.3 0.3 0.3 1" />
        </material>
      </collision>
    </link>
    <joint name="${prefix}/arm_joint6" type="revolute">
      <axis xyz="0 1 0" />
      <limit effort = "10" lower = "-3" upper = "3" velocity = "0.0" />
      <limit effort="150" lower="-0.40" upper="2" velocity="0.0" />
      <parent link="${prefix}/arm_link1" />
      <child link="${prefix}/arm_link6" />
      <origin xyz="0.0132 0 0.0333" rpy=" 0 0 0" />
    </joint> 


    <link name="${prefix}/arm_link6">
      <inertial>
        <origin xyz="-0.014 -0.01391 -0.001062" rpy="0 0 0" />
        <mass value="0.001" />
        <inertia ixx="0.000000074" ixy="-0.000000060" ixz="0.000000055"
          iyy="0.000000951" iyz="-0.000000004" izz="0.000000923" />
      </inertial>
      <visual>
        <geometry>
          <mesh filename="package://oryxbot_description/meshes/swiftpro/Link6.STL" />
        </geometry>
        <origin xyz="-0.0132 0 -0.1056" rpy="0 0 0" />
        <material name="">
          <color rgba="0.3 0.3 0.3 1" />
        </material>
      </visual>
      <collision>
        <geometry>
          <mesh filename="package://oryxbot_description/meshes/swiftpro/Link6.STL" />
        </geometry>
        <origin xyz="-0.0132 0 -0.1056" rpy="0 0 0" />
        <material name="">
          <color rgba="0.3 0.3 0.3 1" />
        </material>
      </collision>
    </link>
    <joint name="${prefix}/arm_joint7" type="revolute">
      <axis xyz="0 1 0" />
      <limit effort="150" lower="-3" upper="3" velocity="0.0" />
      <parent link="${prefix}/arm_link6" />
      <child link="${prefix}/arm_link7" />
      <origin xyz="-0.0455 0 -0.00301" rpy=" 0 0 0" />
    </joint>


    <link name="${prefix}/arm_link7">
      <inertial>
        <origin xyz="-0.001242 -0.013867 0.083246" rpy="0 0 0" />
        <mass value="0.001" />
        <inertia ixx="0.000007052" ixy="0.000000003" ixz="0.000000055"
          iyy="0.000007058" iyz="0.000000117" izz="0.000000039" />
      </inertial>
      <visual>
        <geometry>
          <mesh filename="package://oryxbot_description/meshes/swiftpro/Link7.STL" />
        </geometry>
        <origin xyz="0.0323 0 -0.10258" rpy="0 0 0" />
        <material name="">
          <color rgba="0.3 0.3 0.3 1" />
        </material>
      </visual>
      <collision>
        <geometry>
          <mesh filename="package://oryxbot_description/meshes/swiftpro/Link7.STL" />
        </geometry>
        <origin xyz="0.0323 0 -0.10258" rpy="0 0 0" />
        <material name="">
          <color rgba="0.3 0.3 0.3 1" />
        </material>
      </collision>
    </link>
    <joint name="${prefix}/arm_joint8" type="revolute">
      <axis xyz="0 1 0" />
      <limit effort="150" lower="-3" upper="3" velocity="0.0" />
      <parent link="${prefix}/arm_link3" />
      <child link="${prefix}/arm_link8" />
      <origin xyz="0.15852 0 0" rpy=" 0 0 0" />
    </joint>


    <link name="${prefix}/arm_link8">
      <inertial>
        <origin xyz="0.027288 0.001085 -0.007344" rpy="0 0 0" />
        <mass value="0.001" />
        <inertia ixx="0.000002184" ixy="0.000000020" ixz="-0.000000207"
          iyy="0.000002992" iyz="0.000000371" izz="0.000001832" />
      </inertial>
      <visual>
        <geometry>
          <mesh filename="package://oryxbot_description/meshes/swiftpro/Suction.STL" />
        </geometry>
        <origin xyz="-0.17201 0 -0.24651" rpy="0 0 0" />
        <material name="">
          <color rgba="0.3 0.3 0.3 1" />
        </material>
      </visual>
      <!-- to have a stabile behavior during picking objects, we had to commment this part -->
      <!-- <collision>
        <geometry>
          <mesh filename="package://oryxbot_description/meshes/swiftpro/Suction.STL" />
        </geometry>
        <origin xyz="-0.17201 0 -0.24651" rpy="0 0 0" />
        <material name="">
          <color rgba="0.3 0.3 0.3 1" />
        </material>
      </collision> -->
    </link>
    <joint name="${prefix}/arm_joint9" type="revolute">
      <axis xyz="0 1 0" />
      <limit effort="150" lower="-3" upper="3" velocity="0.0" />
      <parent link="${prefix}/arm_link8" />
      <child link="${prefix}/arm_link9" />
      <origin xyz="0.02741 0 0.02703" rpy=" 0 0 0" />
    </joint>


    <link name="${prefix}/arm_link9">
      <inertial>
        <origin xyz="-0.079305 0.0157 -0.000043" rpy="0 0 0" />
        <mass value="0.001" />
        <inertia ixx="0.000000022" ixy="0.000000000" ixz="-0.000000002"
          iyy="0.000006517" iyz="0.000000000" izz="0.000006497" />
      </inertial>
      <visual>
        <geometry>
          <mesh filename="package://oryxbot_description/meshes/swiftpro/Link9.STL" />
        </geometry>
        <origin xyz="-0.19941 0 -0.27471" rpy="0 0 0" />
        <material name="">
          <color rgba="0.3 0.3 0.3 1" />
        </material>
      </visual>
      <collision>
        <geometry>
          <mesh filename="package://oryxbot_description/meshes/swiftpro/Link9.STL" />
        </geometry>
        <origin xyz="-0.19941 0 -0.27471" rpy="0 0 0" />
        <material name="">
          <color rgba="0.3 0.3 0.3 1" />
        </material>
      </collision>
    </link>
    <joint name="${prefix}/virtual_end_joint" type="revolute">
      <axis xyz="0 0 1" />
      <parent link="${prefix}/arm_link8" />
      <child link="${prefix}/virtual_end_effector" />
      <origin xyz="0.0565 0 -0.07" rpy=" 0 0 0" />
      <limit effort="1" lower="0" upper="0" velocity="0.0" />
    </joint>
    <!-- virtual links needed for vacuum_gripper plugin -->
    <link name="${prefix}/virtual_end_effector">
      <gravity>0</gravity>
      <visual>
        <origin rpy="0 0 0" xyz="0 0 0" />
        <geometry>
          <cylinder radius="0.008" length="0.01" />
        </geometry>
        <material name="transparent">
          <color rgba="0 0 0 0" />
        </material>
      </visual>
      <inertial>
        <origin rpy="0 0 0" xyz="0.000000 0.000000 0.000000" />
        <mass value="0.001" />
        <inertia ixx="0.00000003333" ixy="0" ixz="0"
          iyy="0.00000003333" iyz="0"
          izz="0.00000005" />
      </inertial>
    </link>
    <link name="hand_cam_base_link"/>
    <joint
      name="hand_cam_base_joint"
      type="fixed">
      <origin
        xyz="-0.04 0 0.035"
        rpy="1.57 1.57 0" />
      <parent
        link="${prefix}/virtual_end_effector" />
      <child
        link="hand_cam_base_link" />
      <axis
        xyz="0 0 0" />
    </joint>
    <link name="hand_cam_link"/>
    <joint
      name="hand_cam_joint"
      type="fixed">
      <origin
        xyz="0 0 0"
        rpy="-1.57 0 -1.57" />
      <parent
        link="hand_cam_base_link" />
      <child
        link="hand_cam_link" />
      <axis
        xyz="0 0 0" />
    </joint>
    <xacro:if value="${sim}">
      <xacro:swiftpro_gazebo_plugin prefix="${prefix}" />
    </xacro:if>
  </xacro:macro>
  <!-- <link name="sss" /> -->
</robot>